2025-05-10 02:27:22,652 | INFO | üöÄ –°—Ç–∞—Ä—Ç —Ä–∞—Å—Å—ã–ª–∫–∏: Broadcast ID=10, 1 –ø–æ–ª—É—á–∞—Ç–µ–ª–µ–π
2025-05-10 02:27:22,654 | INFO | üì® –û—Ç–ø—Ä–∞–≤–∫–∞ ‚Üí user_id=8016905018 | @None
2025-05-10 02:27:22,836 | ERROR | üî• –ù–µ–∏–∑–≤–µ—Å—Ç–Ω–∞—è –æ—à–∏–±–∫–∞: IntegrityError: UNIQUE constraint failed: core_broadcastdelivery.message_id, core_broadcastdelivery.recipient_id
Traceback (most recent call last):
  File "/root/crm/venv/lib/python3.9/site-packages/django/db/backends/utils.py", line 89, in _execute
    return self.cursor.execute(sql, params)
  File "/root/crm/venv/lib/python3.9/site-packages/django/db/backends/sqlite3/base.py", line 328, in execute
    return super().execute(query, params)
sqlite3.IntegrityError: UNIQUE constraint failed: core_broadcastdelivery.message_id, core_broadcastdelivery.recipient_id

The above exception was the direct cause of the following exception:

Traceback (most recent call last):
  File "/root/crm/core/admin.py", line 126, in send_broadcast
    BroadcastDelivery.objects.create(
  File "/root/crm/venv/lib/python3.9/site-packages/django/db/models/manager.py", line 87, in manager_method
    return getattr(self.get_queryset(), name)(*args, **kwargs)
  File "/root/crm/venv/lib/python3.9/site-packages/django/db/models/query.py", line 658, in create
    obj.save(force_insert=True, using=self.db)
  File "/root/crm/venv/lib/python3.9/site-packages/django/db/models/base.py", line 814, in save
    self.save_base(
  File "/root/crm/venv/lib/python3.9/site-packages/django/db/models/base.py", line 877, in save_base
    updated = self._save_table(
  File "/root/crm/venv/lib/python3.9/site-packages/django/db/models/base.py", line 1020, in _save_table
    results = self._do_insert(
  File "/root/crm/venv/lib/python3.9/site-packages/django/db/models/base.py", line 1061, in _do_insert
    return manager._insert(
  File "/root/crm/venv/lib/python3.9/site-packages/django/db/models/manager.py", line 87, in manager_method
    return getattr(self.get_queryset(), name)(*args, **kwargs)
  File "/root/crm/venv/lib/python3.9/site-packages/django/db/models/query.py", line 1805, in _insert
    return query.get_compiler(using=using).execute_sql(returning_fields)
  File "/root/crm/venv/lib/python3.9/site-packages/django/db/models/sql/compiler.py", line 1822, in execute_sql
    cursor.execute(sql, params)
  File "/root/crm/venv/lib/python3.9/site-packages/django/db/backends/utils.py", line 102, in execute
    return super().execute(sql, params)
  File "/root/crm/venv/lib/python3.9/site-packages/django/db/backends/utils.py", line 67, in execute
    return self._execute_with_wrappers(
  File "/root/crm/venv/lib/python3.9/site-packages/django/db/backends/utils.py", line 80, in _execute_with_wrappers
    return executor(sql, params, many, context)
  File "/root/crm/venv/lib/python3.9/site-packages/django/db/backends/utils.py", line 89, in _execute
    return self.cursor.execute(sql, params)
  File "/root/crm/venv/lib/python3.9/site-packages/django/db/utils.py", line 91, in __exit__
    raise dj_exc_value.with_traceback(traceback) from exc_value
  File "/root/crm/venv/lib/python3.9/site-packages/django/db/backends/utils.py", line 89, in _execute
    return self.cursor.execute(sql, params)
  File "/root/crm/venv/lib/python3.9/site-packages/django/db/backends/sqlite3/base.py", line 328, in execute
    return super().execute(query, params)
django.db.utils.IntegrityError: UNIQUE constraint failed: core_broadcastdelivery.message_id, core_broadcastdelivery.recipient_id
